# 异步回调函数错误处理

```js
//下列操作中，异步的错误无法被try...catch捕获，请修改
const url = '/sample/api'
try {
	asyncAjaxGet(url, (response) => {
		response.data.children = 1;//可能有异常，期望被捕获
	})
} catch(e){
	console.log('捕获异步错误',e)
}
```



由于异步回调函数是在下一个事件循环中执行的，try catch只能捕获当前循环内的异常

可以利用 Promise 和 async/await 捕获异步回调函数的错误